2025-05-14 02:11:46,283 - WARNING - PyNaCl is not installed, voice will NOT be supported
2025-05-14 02:11:47,059 - INFO - Starting bot...
2025-05-14 02:11:47,059 - INFO - logging in using static token
2025-05-14 02:11:53,198 - INFO - Shard ID None has connected to Gateway (Session ID: 4da5088c724a9da10ae7266ed5269937).
2025-05-14 02:11:55,243 - INFO - Bot logged in as CWL Balance Boss#9976
2025-05-14 02:11:55,243 - INFO - Initializing CoC client...
2025-05-14 02:11:56,820 - INFO - Successfully logged into the developer site.
2025-05-14 02:11:56,821 - INFO - Found IP address to be 103.247.51.91
2025-05-14 02:11:57,668 - INFO - Retrieved 1 valid keys from the developer site.
2025-05-14 02:11:57,668 - INFO - Successfully initialised keys for use.
2025-05-14 02:11:58,498 - INFO - CoC client initialized successfully
2025-05-14 02:11:58,973 - INFO - Slash commands synced to server 1209053585418223646
2025-05-14 18:04:04,461 - WARNING - PyNaCl is not installed, voice will NOT be supported
2025-05-14 18:04:04,545 - INFO - Starting bot...
2025-05-14 18:04:04,545 - INFO - logging in using static token
2025-05-14 18:04:08,072 - INFO - Shard ID None has connected to Gateway (Session ID: 022d5360f6dae0a7675c61eeab45f0ae).
2025-05-14 18:04:10,078 - INFO - Initializing CoC client...
2025-05-14 18:04:11,792 - INFO - Successfully logged into the developer site.
2025-05-14 18:04:11,792 - INFO - Found IP address to be 103.247.51.91
2025-05-14 18:04:12,706 - INFO - Retrieved 1 valid keys from the developer site.
2025-05-14 18:04:12,759 - INFO - Successfully initialised keys for use.
2025-05-14 18:04:13,471 - INFO - CoC client initialized
2025-05-14 18:04:13,484 - ERROR - Sync error for server 1209053585418223646: object NoneType can't be used in 'await' expression
2025-05-14 18:09:22,091 - WARNING - PyNaCl is not installed, voice will NOT be supported
2025-05-14 18:09:22,109 - INFO - Starting bot...
2025-05-14 18:09:22,109 - INFO - logging in using static token
2025-05-14 18:09:25,069 - INFO - Shard ID None has connected to Gateway (Session ID: 2db6880773a456bcfddca8f783148a89).
2025-05-14 18:09:27,092 - INFO - Initializing CoC client...
2025-05-14 18:09:28,436 - INFO - Successfully logged into the developer site.
2025-05-14 18:09:28,436 - INFO - Found IP address to be 103.247.51.91
2025-05-14 18:09:29,389 - INFO - Retrieved 1 valid keys from the developer site.
2025-05-14 18:09:29,389 - INFO - Successfully initialised keys for use.
2025-05-14 18:09:29,710 - INFO - CoC client initialized
2025-05-14 18:09:30,513 - INFO - Slash commands synced to server 1209053585418223646
2025-05-14 18:11:47,645 - ERROR - Attempting a reconnect in 0.20s
Traceback (most recent call last):
  File "C:\Users\DELL\AppData\Local\Programs\Python\Python312\Lib\site-packages\aiohttp\connector.py", line 1357, in _create_direct_connection
    hosts = await self._resolve_host(host, port, traces=traces)
            ^^^^^^^^^^^^^^^^^^^^^^^^^^^^^^^^^^^^^^^^^^^^^^^^^^^
  File "C:\Users\DELL\AppData\Local\Programs\Python\Python312\Lib\site-packages\aiohttp\connector.py", line 995, in _resolve_host
    return await asyncio.shield(resolved_host_task)
           ^^^^^^^^^^^^^^^^^^^^^^^^^^^^^^^^^^^^^^^^
  File "C:\Users\DELL\AppData\Local\Programs\Python\Python312\Lib\site-packages\aiohttp\connector.py", line 1026, in _resolve_host_with_throttle
    addrs = await self._resolver.resolve(host, port, family=self._family)
            ^^^^^^^^^^^^^^^^^^^^^^^^^^^^^^^^^^^^^^^^^^^^^^^^^^^^^^^^^^^^^
  File "C:\Users\DELL\AppData\Local\Programs\Python\Python312\Lib\site-packages\aiohttp\resolver.py", line 39, in resolve
    infos = await self._loop.getaddrinfo(
            ^^^^^^^^^^^^^^^^^^^^^^^^^^^^^
  File "C:\Users\DELL\AppData\Local\Programs\Python\Python312\Lib\asyncio\base_events.py", line 901, in getaddrinfo
    return await self.run_in_executor(
           ^^^^^^^^^^^^^^^^^^^^^^^^^^^
  File "C:\Users\DELL\AppData\Local\Programs\Python\Python312\Lib\concurrent\futures\thread.py", line 58, in run
    result = self.fn(*self.args, **self.kwargs)
             ^^^^^^^^^^^^^^^^^^^^^^^^^^^^^^^^^^
  File "C:\Users\DELL\AppData\Local\Programs\Python\Python312\Lib\socket.py", line 963, in getaddrinfo
    for res in _socket.getaddrinfo(host, port, family, type, proto, flags):
               ^^^^^^^^^^^^^^^^^^^^^^^^^^^^^^^^^^^^^^^^^^^^^^^^^^^^^^^^^^^
socket.gaierror: [Errno 11001] getaddrinfo failed

The above exception was the direct cause of the following exception:

Traceback (most recent call last):
  File "C:\Users\DELL\AppData\Local\Programs\Python\Python312\Lib\site-packages\discord\client.py", line 701, in connect
    self.ws = await asyncio.wait_for(coro, timeout=60.0)
              ^^^^^^^^^^^^^^^^^^^^^^^^^^^^^^^^^^^^^^^^^^
  File "C:\Users\DELL\AppData\Local\Programs\Python\Python312\Lib\asyncio\tasks.py", line 520, in wait_for
    return await fut
           ^^^^^^^^^
  File "C:\Users\DELL\AppData\Local\Programs\Python\Python312\Lib\site-packages\discord\gateway.py", line 375, in from_client
    socket = await client.http.ws_connect(str(url))
             ^^^^^^^^^^^^^^^^^^^^^^^^^^^^^^^^^^^^^^
  File "C:\Users\DELL\AppData\Local\Programs\Python\Python312\Lib\site-packages\discord\http.py", line 554, in ws_connect
    return await self.__session.ws_connect(url, **kwargs)
           ^^^^^^^^^^^^^^^^^^^^^^^^^^^^^^^^^^^^^^^^^^^^^^
  File "C:\Users\DELL\AppData\Local\Programs\Python\Python312\Lib\site-packages\aiohttp\client.py", line 1004, in _ws_connect
    resp = await self.request(
           ^^^^^^^^^^^^^^^^^^^
  File "C:\Users\DELL\AppData\Local\Programs\Python\Python312\Lib\site-packages\aiohttp\client.py", line 703, in _request
    conn = await self._connector.connect(
           ^^^^^^^^^^^^^^^^^^^^^^^^^^^^^^
  File "C:\Users\DELL\AppData\Local\Programs\Python\Python312\Lib\site-packages\aiohttp\connector.py", line 548, in connect
    proto = await self._create_connection(req, traces, timeout)
            ^^^^^^^^^^^^^^^^^^^^^^^^^^^^^^^^^^^^^^^^^^^^^^^^^^^
  File "C:\Users\DELL\AppData\Local\Programs\Python\Python312\Lib\site-packages\aiohttp\connector.py", line 1056, in _create_connection
    _, proto = await self._create_direct_connection(req, traces, timeout)
               ^^^^^^^^^^^^^^^^^^^^^^^^^^^^^^^^^^^^^^^^^^^^^^^^^^^^^^^^^^
  File "C:\Users\DELL\AppData\Local\Programs\Python\Python312\Lib\site-packages\aiohttp\connector.py", line 1363, in _create_direct_connection
    raise ClientConnectorDNSError(req.connection_key, exc) from exc
aiohttp.client_exceptions.ClientConnectorDNSError: Cannot connect to host gateway-us-east1-b.discord.gg:443 ssl:default [getaddrinfo failed]
2025-05-14 18:11:49,843 - ERROR - Attempting a reconnect in 3.69s
Traceback (most recent call last):
  File "C:\Users\DELL\AppData\Local\Programs\Python\Python312\Lib\site-packages\aiohttp\connector.py", line 1357, in _create_direct_connection
    hosts = await self._resolve_host(host, port, traces=traces)
            ^^^^^^^^^^^^^^^^^^^^^^^^^^^^^^^^^^^^^^^^^^^^^^^^^^^
  File "C:\Users\DELL\AppData\Local\Programs\Python\Python312\Lib\site-packages\aiohttp\connector.py", line 995, in _resolve_host
    return await asyncio.shield(resolved_host_task)
           ^^^^^^^^^^^^^^^^^^^^^^^^^^^^^^^^^^^^^^^^
  File "C:\Users\DELL\AppData\Local\Programs\Python\Python312\Lib\site-packages\aiohttp\connector.py", line 1026, in _resolve_host_with_throttle
    addrs = await self._resolver.resolve(host, port, family=self._family)
            ^^^^^^^^^^^^^^^^^^^^^^^^^^^^^^^^^^^^^^^^^^^^^^^^^^^^^^^^^^^^^
  File "C:\Users\DELL\AppData\Local\Programs\Python\Python312\Lib\site-packages\aiohttp\resolver.py", line 39, in resolve
    infos = await self._loop.getaddrinfo(
            ^^^^^^^^^^^^^^^^^^^^^^^^^^^^^
  File "C:\Users\DELL\AppData\Local\Programs\Python\Python312\Lib\asyncio\base_events.py", line 901, in getaddrinfo
    return await self.run_in_executor(
           ^^^^^^^^^^^^^^^^^^^^^^^^^^^
  File "C:\Users\DELL\AppData\Local\Programs\Python\Python312\Lib\concurrent\futures\thread.py", line 58, in run
    result = self.fn(*self.args, **self.kwargs)
             ^^^^^^^^^^^^^^^^^^^^^^^^^^^^^^^^^^
  File "C:\Users\DELL\AppData\Local\Programs\Python\Python312\Lib\socket.py", line 963, in getaddrinfo
    for res in _socket.getaddrinfo(host, port, family, type, proto, flags):
               ^^^^^^^^^^^^^^^^^^^^^^^^^^^^^^^^^^^^^^^^^^^^^^^^^^^^^^^^^^^
socket.gaierror: [Errno 11001] getaddrinfo failed

The above exception was the direct cause of the following exception:

Traceback (most recent call last):
  File "C:\Users\DELL\AppData\Local\Programs\Python\Python312\Lib\site-packages\discord\client.py", line 701, in connect
    self.ws = await asyncio.wait_for(coro, timeout=60.0)
              ^^^^^^^^^^^^^^^^^^^^^^^^^^^^^^^^^^^^^^^^^^
  File "C:\Users\DELL\AppData\Local\Programs\Python\Python312\Lib\asyncio\tasks.py", line 520, in wait_for
    return await fut
           ^^^^^^^^^
  File "C:\Users\DELL\AppData\Local\Programs\Python\Python312\Lib\site-packages\discord\gateway.py", line 375, in from_client
    socket = await client.http.ws_connect(str(url))
             ^^^^^^^^^^^^^^^^^^^^^^^^^^^^^^^^^^^^^^
  File "C:\Users\DELL\AppData\Local\Programs\Python\Python312\Lib\site-packages\discord\http.py", line 554, in ws_connect
    return await self.__session.ws_connect(url, **kwargs)
           ^^^^^^^^^^^^^^^^^^^^^^^^^^^^^^^^^^^^^^^^^^^^^^
  File "C:\Users\DELL\AppData\Local\Programs\Python\Python312\Lib\site-packages\aiohttp\client.py", line 1004, in _ws_connect
    resp = await self.request(
           ^^^^^^^^^^^^^^^^^^^
  File "C:\Users\DELL\AppData\Local\Programs\Python\Python312\Lib\site-packages\aiohttp\client.py", line 703, in _request
    conn = await self._connector.connect(
           ^^^^^^^^^^^^^^^^^^^^^^^^^^^^^^
  File "C:\Users\DELL\AppData\Local\Programs\Python\Python312\Lib\site-packages\aiohttp\connector.py", line 548, in connect
    proto = await self._create_connection(req, traces, timeout)
            ^^^^^^^^^^^^^^^^^^^^^^^^^^^^^^^^^^^^^^^^^^^^^^^^^^^
  File "C:\Users\DELL\AppData\Local\Programs\Python\Python312\Lib\site-packages\aiohttp\connector.py", line 1056, in _create_connection
    _, proto = await self._create_direct_connection(req, traces, timeout)
               ^^^^^^^^^^^^^^^^^^^^^^^^^^^^^^^^^^^^^^^^^^^^^^^^^^^^^^^^^^
  File "C:\Users\DELL\AppData\Local\Programs\Python\Python312\Lib\site-packages\aiohttp\connector.py", line 1363, in _create_direct_connection
    raise ClientConnectorDNSError(req.connection_key, exc) from exc
aiohttp.client_exceptions.ClientConnectorDNSError: Cannot connect to host gateway-us-east1-b.discord.gg:443 ssl:default [getaddrinfo failed]
2025-05-14 18:11:58,830 - ERROR - Attempting a reconnect in 3.33s
Traceback (most recent call last):
  File "C:\Users\DELL\AppData\Local\Programs\Python\Python312\Lib\site-packages\aiohttp\connector.py", line 1357, in _create_direct_connection
    hosts = await self._resolve_host(host, port, traces=traces)
            ^^^^^^^^^^^^^^^^^^^^^^^^^^^^^^^^^^^^^^^^^^^^^^^^^^^
  File "C:\Users\DELL\AppData\Local\Programs\Python\Python312\Lib\site-packages\aiohttp\connector.py", line 995, in _resolve_host
    return await asyncio.shield(resolved_host_task)
           ^^^^^^^^^^^^^^^^^^^^^^^^^^^^^^^^^^^^^^^^
  File "C:\Users\DELL\AppData\Local\Programs\Python\Python312\Lib\site-packages\aiohttp\connector.py", line 1026, in _resolve_host_with_throttle
    addrs = await self._resolver.resolve(host, port, family=self._family)
            ^^^^^^^^^^^^^^^^^^^^^^^^^^^^^^^^^^^^^^^^^^^^^^^^^^^^^^^^^^^^^
  File "C:\Users\DELL\AppData\Local\Programs\Python\Python312\Lib\site-packages\aiohttp\resolver.py", line 39, in resolve
    infos = await self._loop.getaddrinfo(
            ^^^^^^^^^^^^^^^^^^^^^^^^^^^^^
  File "C:\Users\DELL\AppData\Local\Programs\Python\Python312\Lib\asyncio\base_events.py", line 901, in getaddrinfo
    return await self.run_in_executor(
           ^^^^^^^^^^^^^^^^^^^^^^^^^^^
  File "C:\Users\DELL\AppData\Local\Programs\Python\Python312\Lib\concurrent\futures\thread.py", line 58, in run
    result = self.fn(*self.args, **self.kwargs)
             ^^^^^^^^^^^^^^^^^^^^^^^^^^^^^^^^^^
  File "C:\Users\DELL\AppData\Local\Programs\Python\Python312\Lib\socket.py", line 963, in getaddrinfo
    for res in _socket.getaddrinfo(host, port, family, type, proto, flags):
               ^^^^^^^^^^^^^^^^^^^^^^^^^^^^^^^^^^^^^^^^^^^^^^^^^^^^^^^^^^^
socket.gaierror: [Errno 11001] getaddrinfo failed

The above exception was the direct cause of the following exception:

Traceback (most recent call last):
  File "C:\Users\DELL\AppData\Local\Programs\Python\Python312\Lib\site-packages\discord\client.py", line 701, in connect
    self.ws = await asyncio.wait_for(coro, timeout=60.0)
              ^^^^^^^^^^^^^^^^^^^^^^^^^^^^^^^^^^^^^^^^^^
  File "C:\Users\DELL\AppData\Local\Programs\Python\Python312\Lib\asyncio\tasks.py", line 520, in wait_for
    return await fut
           ^^^^^^^^^
  File "C:\Users\DELL\AppData\Local\Programs\Python\Python312\Lib\site-packages\discord\gateway.py", line 375, in from_client
    socket = await client.http.ws_connect(str(url))
             ^^^^^^^^^^^^^^^^^^^^^^^^^^^^^^^^^^^^^^
  File "C:\Users\DELL\AppData\Local\Programs\Python\Python312\Lib\site-packages\discord\http.py", line 554, in ws_connect
    return await self.__session.ws_connect(url, **kwargs)
           ^^^^^^^^^^^^^^^^^^^^^^^^^^^^^^^^^^^^^^^^^^^^^^
  File "C:\Users\DELL\AppData\Local\Programs\Python\Python312\Lib\site-packages\aiohttp\client.py", line 1004, in _ws_connect
    resp = await self.request(
           ^^^^^^^^^^^^^^^^^^^
  File "C:\Users\DELL\AppData\Local\Programs\Python\Python312\Lib\site-packages\aiohttp\client.py", line 703, in _request
    conn = await self._connector.connect(
           ^^^^^^^^^^^^^^^^^^^^^^^^^^^^^^
  File "C:\Users\DELL\AppData\Local\Programs\Python\Python312\Lib\site-packages\aiohttp\connector.py", line 548, in connect
    proto = await self._create_connection(req, traces, timeout)
            ^^^^^^^^^^^^^^^^^^^^^^^^^^^^^^^^^^^^^^^^^^^^^^^^^^^
  File "C:\Users\DELL\AppData\Local\Programs\Python\Python312\Lib\site-packages\aiohttp\connector.py", line 1056, in _create_connection
    _, proto = await self._create_direct_connection(req, traces, timeout)
               ^^^^^^^^^^^^^^^^^^^^^^^^^^^^^^^^^^^^^^^^^^^^^^^^^^^^^^^^^^
  File "C:\Users\DELL\AppData\Local\Programs\Python\Python312\Lib\site-packages\aiohttp\connector.py", line 1363, in _create_direct_connection
    raise ClientConnectorDNSError(req.connection_key, exc) from exc
aiohttp.client_exceptions.ClientConnectorDNSError: Cannot connect to host gateway-us-east1-b.discord.gg:443 ssl:default [getaddrinfo failed]
2025-05-14 18:12:02,170 - ERROR - Attempting a reconnect in 8.53s
Traceback (most recent call last):
  File "C:\Users\DELL\AppData\Local\Programs\Python\Python312\Lib\site-packages\aiohttp\connector.py", line 1357, in _create_direct_connection
    hosts = await self._resolve_host(host, port, traces=traces)
            ^^^^^^^^^^^^^^^^^^^^^^^^^^^^^^^^^^^^^^^^^^^^^^^^^^^
  File "C:\Users\DELL\AppData\Local\Programs\Python\Python312\Lib\site-packages\aiohttp\connector.py", line 995, in _resolve_host
    return await asyncio.shield(resolved_host_task)
           ^^^^^^^^^^^^^^^^^^^^^^^^^^^^^^^^^^^^^^^^
  File "C:\Users\DELL\AppData\Local\Programs\Python\Python312\Lib\site-packages\aiohttp\connector.py", line 1026, in _resolve_host_with_throttle
    addrs = await self._resolver.resolve(host, port, family=self._family)
            ^^^^^^^^^^^^^^^^^^^^^^^^^^^^^^^^^^^^^^^^^^^^^^^^^^^^^^^^^^^^^
  File "C:\Users\DELL\AppData\Local\Programs\Python\Python312\Lib\site-packages\aiohttp\resolver.py", line 39, in resolve
    infos = await self._loop.getaddrinfo(
            ^^^^^^^^^^^^^^^^^^^^^^^^^^^^^
  File "C:\Users\DELL\AppData\Local\Programs\Python\Python312\Lib\asyncio\base_events.py", line 901, in getaddrinfo
    return await self.run_in_executor(
           ^^^^^^^^^^^^^^^^^^^^^^^^^^^
  File "C:\Users\DELL\AppData\Local\Programs\Python\Python312\Lib\concurrent\futures\thread.py", line 58, in run
    result = self.fn(*self.args, **self.kwargs)
             ^^^^^^^^^^^^^^^^^^^^^^^^^^^^^^^^^^
  File "C:\Users\DELL\AppData\Local\Programs\Python\Python312\Lib\socket.py", line 963, in getaddrinfo
    for res in _socket.getaddrinfo(host, port, family, type, proto, flags):
               ^^^^^^^^^^^^^^^^^^^^^^^^^^^^^^^^^^^^^^^^^^^^^^^^^^^^^^^^^^^
socket.gaierror: [Errno 11001] getaddrinfo failed

The above exception was the direct cause of the following exception:

Traceback (most recent call last):
  File "C:\Users\DELL\AppData\Local\Programs\Python\Python312\Lib\site-packages\discord\client.py", line 701, in connect
    self.ws = await asyncio.wait_for(coro, timeout=60.0)
              ^^^^^^^^^^^^^^^^^^^^^^^^^^^^^^^^^^^^^^^^^^
  File "C:\Users\DELL\AppData\Local\Programs\Python\Python312\Lib\asyncio\tasks.py", line 520, in wait_for
    return await fut
           ^^^^^^^^^
  File "C:\Users\DELL\AppData\Local\Programs\Python\Python312\Lib\site-packages\discord\gateway.py", line 375, in from_client
    socket = await client.http.ws_connect(str(url))
             ^^^^^^^^^^^^^^^^^^^^^^^^^^^^^^^^^^^^^^
  File "C:\Users\DELL\AppData\Local\Programs\Python\Python312\Lib\site-packages\discord\http.py", line 554, in ws_connect
    return await self.__session.ws_connect(url, **kwargs)
           ^^^^^^^^^^^^^^^^^^^^^^^^^^^^^^^^^^^^^^^^^^^^^^
  File "C:\Users\DELL\AppData\Local\Programs\Python\Python312\Lib\site-packages\aiohttp\client.py", line 1004, in _ws_connect
    resp = await self.request(
           ^^^^^^^^^^^^^^^^^^^
  File "C:\Users\DELL\AppData\Local\Programs\Python\Python312\Lib\site-packages\aiohttp\client.py", line 703, in _request
    conn = await self._connector.connect(
           ^^^^^^^^^^^^^^^^^^^^^^^^^^^^^^
  File "C:\Users\DELL\AppData\Local\Programs\Python\Python312\Lib\site-packages\aiohttp\connector.py", line 548, in connect
    proto = await self._create_connection(req, traces, timeout)
            ^^^^^^^^^^^^^^^^^^^^^^^^^^^^^^^^^^^^^^^^^^^^^^^^^^^
  File "C:\Users\DELL\AppData\Local\Programs\Python\Python312\Lib\site-packages\aiohttp\connector.py", line 1056, in _create_connection
    _, proto = await self._create_direct_connection(req, traces, timeout)
               ^^^^^^^^^^^^^^^^^^^^^^^^^^^^^^^^^^^^^^^^^^^^^^^^^^^^^^^^^^
  File "C:\Users\DELL\AppData\Local\Programs\Python\Python312\Lib\site-packages\aiohttp\connector.py", line 1363, in _create_direct_connection
    raise ClientConnectorDNSError(req.connection_key, exc) from exc
aiohttp.client_exceptions.ClientConnectorDNSError: Cannot connect to host gateway-us-east1-b.discord.gg:443 ssl:default [getaddrinfo failed]
2025-05-14 18:12:11,897 - INFO - Shard ID None has successfully RESUMED session 2db6880773a456bcfddca8f783148a89.
2025-05-14 18:12:55,557 - ERROR - Ignoring exception in command 'update_all'
Traceback (most recent call last):
  File "C:\Users\DELL\AppData\Local\Programs\Python\Python312\Lib\site-packages\discord\app_commands\commands.py", line 858, in _do_call
    return await self._callback(interaction, **params)  # type: ignore
           ^^^^^^^^^^^^^^^^^^^^^^^^^^^^^^^^^^^^^^^^^^^
  File "D:\CWL\botfiles\coctest.py", line 146, in update_all
    await interaction.response.send_message(embed=embed)
  File "C:\Users\DELL\AppData\Local\Programs\Python\Python312\Lib\site-packages\discord\interactions.py", line 1004, in send_message
    response = await adapter.create_interaction_response(
               ^^^^^^^^^^^^^^^^^^^^^^^^^^^^^^^^^^^^^^^^^^
  File "C:\Users\DELL\AppData\Local\Programs\Python\Python312\Lib\site-packages\discord\webhook\async_.py", line 224, in request
    raise NotFound(response, data)
discord.errors.NotFound: 404 Not Found (error code: 10062): Unknown interaction

The above exception was the direct cause of the following exception:

Traceback (most recent call last):
  File "C:\Users\DELL\AppData\Local\Programs\Python\Python312\Lib\site-packages\discord\app_commands\tree.py", line 1310, in _call
    await command._invoke_with_namespace(interaction, namespace)
  File "C:\Users\DELL\AppData\Local\Programs\Python\Python312\Lib\site-packages\discord\app_commands\commands.py", line 883, in _invoke_with_namespace
    return await self._do_call(interaction, transformed_values)
           ^^^^^^^^^^^^^^^^^^^^^^^^^^^^^^^^^^^^^^^^^^^^^^^^^^^^
  File "C:\Users\DELL\AppData\Local\Programs\Python\Python312\Lib\site-packages\discord\app_commands\commands.py", line 876, in _do_call
    raise CommandInvokeError(self, e) from e
discord.app_commands.errors.CommandInvokeError: Command 'update_all' raised an exception: NotFound: 404 Not Found (error code: 10062): Unknown interaction
2025-05-14 18:13:13,130 - ERROR - Ignoring exception in command 'profile'
Traceback (most recent call last):
  File "C:\Users\DELL\AppData\Local\Programs\Python\Python312\Lib\site-packages\discord\app_commands\commands.py", line 858, in _do_call
    return await self._callback(interaction, **params)  # type: ignore
           ^^^^^^^^^^^^^^^^^^^^^^^^^^^^^^^^^^^^^^^^^^^
  File "D:\CWL\botfiles\coctest.py", line 182, in profile
    await interaction.response.send_message(embed=embed)
  File "C:\Users\DELL\AppData\Local\Programs\Python\Python312\Lib\site-packages\discord\interactions.py", line 1004, in send_message
    response = await adapter.create_interaction_response(
               ^^^^^^^^^^^^^^^^^^^^^^^^^^^^^^^^^^^^^^^^^^
  File "C:\Users\DELL\AppData\Local\Programs\Python\Python312\Lib\site-packages\discord\webhook\async_.py", line 224, in request
    raise NotFound(response, data)
discord.errors.NotFound: 404 Not Found (error code: 10062): Unknown interaction

The above exception was the direct cause of the following exception:

Traceback (most recent call last):
  File "C:\Users\DELL\AppData\Local\Programs\Python\Python312\Lib\site-packages\discord\app_commands\tree.py", line 1310, in _call
    await command._invoke_with_namespace(interaction, namespace)
  File "C:\Users\DELL\AppData\Local\Programs\Python\Python312\Lib\site-packages\discord\app_commands\commands.py", line 883, in _invoke_with_namespace
    return await self._do_call(interaction, transformed_values)
           ^^^^^^^^^^^^^^^^^^^^^^^^^^^^^^^^^^^^^^^^^^^^^^^^^^^^
  File "C:\Users\DELL\AppData\Local\Programs\Python\Python312\Lib\site-packages\discord\app_commands\commands.py", line 876, in _do_call
    raise CommandInvokeError(self, e) from e
discord.app_commands.errors.CommandInvokeError: Command 'profile' raised an exception: NotFound: 404 Not Found (error code: 10062): Unknown interaction
2025-05-14 18:18:14,761 - ERROR - Attempting a reconnect in 24.85s
Traceback (most recent call last):
  File "C:\Users\DELL\AppData\Local\Programs\Python\Python312\Lib\site-packages\aiohttp\connector.py", line 1357, in _create_direct_connection
    hosts = await self._resolve_host(host, port, traces=traces)
            ^^^^^^^^^^^^^^^^^^^^^^^^^^^^^^^^^^^^^^^^^^^^^^^^^^^
  File "C:\Users\DELL\AppData\Local\Programs\Python\Python312\Lib\site-packages\aiohttp\connector.py", line 995, in _resolve_host
    return await asyncio.shield(resolved_host_task)
           ^^^^^^^^^^^^^^^^^^^^^^^^^^^^^^^^^^^^^^^^
  File "C:\Users\DELL\AppData\Local\Programs\Python\Python312\Lib\site-packages\aiohttp\connector.py", line 1026, in _resolve_host_with_throttle
    addrs = await self._resolver.resolve(host, port, family=self._family)
            ^^^^^^^^^^^^^^^^^^^^^^^^^^^^^^^^^^^^^^^^^^^^^^^^^^^^^^^^^^^^^
  File "C:\Users\DELL\AppData\Local\Programs\Python\Python312\Lib\site-packages\aiohttp\resolver.py", line 39, in resolve
    infos = await self._loop.getaddrinfo(
            ^^^^^^^^^^^^^^^^^^^^^^^^^^^^^
  File "C:\Users\DELL\AppData\Local\Programs\Python\Python312\Lib\asyncio\base_events.py", line 901, in getaddrinfo
    return await self.run_in_executor(
           ^^^^^^^^^^^^^^^^^^^^^^^^^^^
  File "C:\Users\DELL\AppData\Local\Programs\Python\Python312\Lib\concurrent\futures\thread.py", line 58, in run
    result = self.fn(*self.args, **self.kwargs)
             ^^^^^^^^^^^^^^^^^^^^^^^^^^^^^^^^^^
  File "C:\Users\DELL\AppData\Local\Programs\Python\Python312\Lib\socket.py", line 963, in getaddrinfo
    for res in _socket.getaddrinfo(host, port, family, type, proto, flags):
               ^^^^^^^^^^^^^^^^^^^^^^^^^^^^^^^^^^^^^^^^^^^^^^^^^^^^^^^^^^^
socket.gaierror: [Errno 11001] getaddrinfo failed

The above exception was the direct cause of the following exception:

Traceback (most recent call last):
  File "C:\Users\DELL\AppData\Local\Programs\Python\Python312\Lib\site-packages\discord\client.py", line 701, in connect
    self.ws = await asyncio.wait_for(coro, timeout=60.0)
              ^^^^^^^^^^^^^^^^^^^^^^^^^^^^^^^^^^^^^^^^^^
  File "C:\Users\DELL\AppData\Local\Programs\Python\Python312\Lib\asyncio\tasks.py", line 520, in wait_for
    return await fut
           ^^^^^^^^^
  File "C:\Users\DELL\AppData\Local\Programs\Python\Python312\Lib\site-packages\discord\gateway.py", line 375, in from_client
    socket = await client.http.ws_connect(str(url))
             ^^^^^^^^^^^^^^^^^^^^^^^^^^^^^^^^^^^^^^
  File "C:\Users\DELL\AppData\Local\Programs\Python\Python312\Lib\site-packages\discord\http.py", line 554, in ws_connect
    return await self.__session.ws_connect(url, **kwargs)
           ^^^^^^^^^^^^^^^^^^^^^^^^^^^^^^^^^^^^^^^^^^^^^^
  File "C:\Users\DELL\AppData\Local\Programs\Python\Python312\Lib\site-packages\aiohttp\client.py", line 1004, in _ws_connect
    resp = await self.request(
           ^^^^^^^^^^^^^^^^^^^
  File "C:\Users\DELL\AppData\Local\Programs\Python\Python312\Lib\site-packages\aiohttp\client.py", line 703, in _request
    conn = await self._connector.connect(
           ^^^^^^^^^^^^^^^^^^^^^^^^^^^^^^
  File "C:\Users\DELL\AppData\Local\Programs\Python\Python312\Lib\site-packages\aiohttp\connector.py", line 548, in connect
    proto = await self._create_connection(req, traces, timeout)
            ^^^^^^^^^^^^^^^^^^^^^^^^^^^^^^^^^^^^^^^^^^^^^^^^^^^
  File "C:\Users\DELL\AppData\Local\Programs\Python\Python312\Lib\site-packages\aiohttp\connector.py", line 1056, in _create_connection
    _, proto = await self._create_direct_connection(req, traces, timeout)
               ^^^^^^^^^^^^^^^^^^^^^^^^^^^^^^^^^^^^^^^^^^^^^^^^^^^^^^^^^^
  File "C:\Users\DELL\AppData\Local\Programs\Python\Python312\Lib\site-packages\aiohttp\connector.py", line 1363, in _create_direct_connection
    raise ClientConnectorDNSError(req.connection_key, exc) from exc
aiohttp.client_exceptions.ClientConnectorDNSError: Cannot connect to host gateway-us-east1-b.discord.gg:443 ssl:default [getaddrinfo failed]
2025-05-14 18:18:41,337 - INFO - Shard ID None has successfully RESUMED session 2db6880773a456bcfddca8f783148a89.
2025-05-14 18:18:46,076 - ERROR - Ignoring exception in command 'update_all'
Traceback (most recent call last):
  File "C:\Users\DELL\AppData\Local\Programs\Python\Python312\Lib\site-packages\discord\app_commands\commands.py", line 858, in _do_call
    return await self._callback(interaction, **params)  # type: ignore
           ^^^^^^^^^^^^^^^^^^^^^^^^^^^^^^^^^^^^^^^^^^^
  File "D:\CWL\botfiles\coctest.py", line 146, in update_all
    await interaction.response.send_message(embed=embed)
  File "C:\Users\DELL\AppData\Local\Programs\Python\Python312\Lib\site-packages\discord\interactions.py", line 1004, in send_message
    response = await adapter.create_interaction_response(
               ^^^^^^^^^^^^^^^^^^^^^^^^^^^^^^^^^^^^^^^^^^
  File "C:\Users\DELL\AppData\Local\Programs\Python\Python312\Lib\site-packages\discord\webhook\async_.py", line 224, in request
    raise NotFound(response, data)
discord.errors.NotFound: 404 Not Found (error code: 10062): Unknown interaction

The above exception was the direct cause of the following exception:

Traceback (most recent call last):
  File "C:\Users\DELL\AppData\Local\Programs\Python\Python312\Lib\site-packages\discord\app_commands\tree.py", line 1310, in _call
    await command._invoke_with_namespace(interaction, namespace)
  File "C:\Users\DELL\AppData\Local\Programs\Python\Python312\Lib\site-packages\discord\app_commands\commands.py", line 883, in _invoke_with_namespace
    return await self._do_call(interaction, transformed_values)
           ^^^^^^^^^^^^^^^^^^^^^^^^^^^^^^^^^^^^^^^^^^^^^^^^^^^^
  File "C:\Users\DELL\AppData\Local\Programs\Python\Python312\Lib\site-packages\discord\app_commands\commands.py", line 876, in _do_call
    raise CommandInvokeError(self, e) from e
discord.app_commands.errors.CommandInvokeError: Command 'update_all' raised an exception: NotFound: 404 Not Found (error code: 10062): Unknown interaction
2025-05-14 18:23:18,804 - ERROR - Attempting a reconnect in 20.38s
Traceback (most recent call last):
  File "C:\Users\DELL\AppData\Local\Programs\Python\Python312\Lib\site-packages\aiohttp\connector.py", line 1357, in _create_direct_connection
    hosts = await self._resolve_host(host, port, traces=traces)
            ^^^^^^^^^^^^^^^^^^^^^^^^^^^^^^^^^^^^^^^^^^^^^^^^^^^
  File "C:\Users\DELL\AppData\Local\Programs\Python\Python312\Lib\site-packages\aiohttp\connector.py", line 995, in _resolve_host
    return await asyncio.shield(resolved_host_task)
           ^^^^^^^^^^^^^^^^^^^^^^^^^^^^^^^^^^^^^^^^
  File "C:\Users\DELL\AppData\Local\Programs\Python\Python312\Lib\site-packages\aiohttp\connector.py", line 1026, in _resolve_host_with_throttle
    addrs = await self._resolver.resolve(host, port, family=self._family)
            ^^^^^^^^^^^^^^^^^^^^^^^^^^^^^^^^^^^^^^^^^^^^^^^^^^^^^^^^^^^^^
  File "C:\Users\DELL\AppData\Local\Programs\Python\Python312\Lib\site-packages\aiohttp\resolver.py", line 39, in resolve
    infos = await self._loop.getaddrinfo(
            ^^^^^^^^^^^^^^^^^^^^^^^^^^^^^
  File "C:\Users\DELL\AppData\Local\Programs\Python\Python312\Lib\asyncio\base_events.py", line 901, in getaddrinfo
    return await self.run_in_executor(
           ^^^^^^^^^^^^^^^^^^^^^^^^^^^
  File "C:\Users\DELL\AppData\Local\Programs\Python\Python312\Lib\concurrent\futures\thread.py", line 58, in run
    result = self.fn(*self.args, **self.kwargs)
             ^^^^^^^^^^^^^^^^^^^^^^^^^^^^^^^^^^
  File "C:\Users\DELL\AppData\Local\Programs\Python\Python312\Lib\socket.py", line 963, in getaddrinfo
    for res in _socket.getaddrinfo(host, port, family, type, proto, flags):
               ^^^^^^^^^^^^^^^^^^^^^^^^^^^^^^^^^^^^^^^^^^^^^^^^^^^^^^^^^^^
socket.gaierror: [Errno 11001] getaddrinfo failed

The above exception was the direct cause of the following exception:

Traceback (most recent call last):
  File "C:\Users\DELL\AppData\Local\Programs\Python\Python312\Lib\site-packages\discord\client.py", line 701, in connect
    self.ws = await asyncio.wait_for(coro, timeout=60.0)
              ^^^^^^^^^^^^^^^^^^^^^^^^^^^^^^^^^^^^^^^^^^
  File "C:\Users\DELL\AppData\Local\Programs\Python\Python312\Lib\asyncio\tasks.py", line 520, in wait_for
    return await fut
           ^^^^^^^^^
  File "C:\Users\DELL\AppData\Local\Programs\Python\Python312\Lib\site-packages\discord\gateway.py", line 375, in from_client
    socket = await client.http.ws_connect(str(url))
             ^^^^^^^^^^^^^^^^^^^^^^^^^^^^^^^^^^^^^^
  File "C:\Users\DELL\AppData\Local\Programs\Python\Python312\Lib\site-packages\discord\http.py", line 554, in ws_connect
    return await self.__session.ws_connect(url, **kwargs)
           ^^^^^^^^^^^^^^^^^^^^^^^^^^^^^^^^^^^^^^^^^^^^^^
  File "C:\Users\DELL\AppData\Local\Programs\Python\Python312\Lib\site-packages\aiohttp\client.py", line 1004, in _ws_connect
    resp = await self.request(
           ^^^^^^^^^^^^^^^^^^^
  File "C:\Users\DELL\AppData\Local\Programs\Python\Python312\Lib\site-packages\aiohttp\client.py", line 703, in _request
    conn = await self._connector.connect(
           ^^^^^^^^^^^^^^^^^^^^^^^^^^^^^^
  File "C:\Users\DELL\AppData\Local\Programs\Python\Python312\Lib\site-packages\aiohttp\connector.py", line 548, in connect
    proto = await self._create_connection(req, traces, timeout)
            ^^^^^^^^^^^^^^^^^^^^^^^^^^^^^^^^^^^^^^^^^^^^^^^^^^^
  File "C:\Users\DELL\AppData\Local\Programs\Python\Python312\Lib\site-packages\aiohttp\connector.py", line 1056, in _create_connection
    _, proto = await self._create_direct_connection(req, traces, timeout)
               ^^^^^^^^^^^^^^^^^^^^^^^^^^^^^^^^^^^^^^^^^^^^^^^^^^^^^^^^^^
  File "C:\Users\DELL\AppData\Local\Programs\Python\Python312\Lib\site-packages\aiohttp\connector.py", line 1363, in _create_direct_connection
    raise ClientConnectorDNSError(req.connection_key, exc) from exc
aiohttp.client_exceptions.ClientConnectorDNSError: Cannot connect to host gateway-us-east1-b.discord.gg:443 ssl:default [getaddrinfo failed]
2025-05-14 18:23:47,609 - INFO - Shard ID None has successfully RESUMED session 2db6880773a456bcfddca8f783148a89.
2025-05-14 18:27:16,492 - INFO - Shard ID None has successfully RESUMED session 2db6880773a456bcfddca8f783148a89.
2025-05-14 18:30:36,107 - ERROR - Attempting a reconnect in 65.12s
Traceback (most recent call last):
  File "C:\Users\DELL\AppData\Local\Programs\Python\Python312\Lib\site-packages\aiohttp\connector.py", line 1357, in _create_direct_connection
    hosts = await self._resolve_host(host, port, traces=traces)
            ^^^^^^^^^^^^^^^^^^^^^^^^^^^^^^^^^^^^^^^^^^^^^^^^^^^
  File "C:\Users\DELL\AppData\Local\Programs\Python\Python312\Lib\site-packages\aiohttp\connector.py", line 995, in _resolve_host
    return await asyncio.shield(resolved_host_task)
           ^^^^^^^^^^^^^^^^^^^^^^^^^^^^^^^^^^^^^^^^
  File "C:\Users\DELL\AppData\Local\Programs\Python\Python312\Lib\site-packages\aiohttp\connector.py", line 1026, in _resolve_host_with_throttle
    addrs = await self._resolver.resolve(host, port, family=self._family)
            ^^^^^^^^^^^^^^^^^^^^^^^^^^^^^^^^^^^^^^^^^^^^^^^^^^^^^^^^^^^^^
  File "C:\Users\DELL\AppData\Local\Programs\Python\Python312\Lib\site-packages\aiohttp\resolver.py", line 39, in resolve
    infos = await self._loop.getaddrinfo(
            ^^^^^^^^^^^^^^^^^^^^^^^^^^^^^
  File "C:\Users\DELL\AppData\Local\Programs\Python\Python312\Lib\asyncio\base_events.py", line 901, in getaddrinfo
    return await self.run_in_executor(
           ^^^^^^^^^^^^^^^^^^^^^^^^^^^
  File "C:\Users\DELL\AppData\Local\Programs\Python\Python312\Lib\concurrent\futures\thread.py", line 58, in run
    result = self.fn(*self.args, **self.kwargs)
             ^^^^^^^^^^^^^^^^^^^^^^^^^^^^^^^^^^
  File "C:\Users\DELL\AppData\Local\Programs\Python\Python312\Lib\socket.py", line 963, in getaddrinfo
    for res in _socket.getaddrinfo(host, port, family, type, proto, flags):
               ^^^^^^^^^^^^^^^^^^^^^^^^^^^^^^^^^^^^^^^^^^^^^^^^^^^^^^^^^^^
socket.gaierror: [Errno 11001] getaddrinfo failed

The above exception was the direct cause of the following exception:

Traceback (most recent call last):
  File "C:\Users\DELL\AppData\Local\Programs\Python\Python312\Lib\site-packages\discord\client.py", line 701, in connect
    self.ws = await asyncio.wait_for(coro, timeout=60.0)
              ^^^^^^^^^^^^^^^^^^^^^^^^^^^^^^^^^^^^^^^^^^
  File "C:\Users\DELL\AppData\Local\Programs\Python\Python312\Lib\asyncio\tasks.py", line 520, in wait_for
    return await fut
           ^^^^^^^^^
  File "C:\Users\DELL\AppData\Local\Programs\Python\Python312\Lib\site-packages\discord\gateway.py", line 375, in from_client
    socket = await client.http.ws_connect(str(url))
             ^^^^^^^^^^^^^^^^^^^^^^^^^^^^^^^^^^^^^^
  File "C:\Users\DELL\AppData\Local\Programs\Python\Python312\Lib\site-packages\discord\http.py", line 554, in ws_connect
    return await self.__session.ws_connect(url, **kwargs)
           ^^^^^^^^^^^^^^^^^^^^^^^^^^^^^^^^^^^^^^^^^^^^^^
  File "C:\Users\DELL\AppData\Local\Programs\Python\Python312\Lib\site-packages\aiohttp\client.py", line 1004, in _ws_connect
    resp = await self.request(
           ^^^^^^^^^^^^^^^^^^^
  File "C:\Users\DELL\AppData\Local\Programs\Python\Python312\Lib\site-packages\aiohttp\client.py", line 703, in _request
    conn = await self._connector.connect(
           ^^^^^^^^^^^^^^^^^^^^^^^^^^^^^^
  File "C:\Users\DELL\AppData\Local\Programs\Python\Python312\Lib\site-packages\aiohttp\connector.py", line 548, in connect
    proto = await self._create_connection(req, traces, timeout)
            ^^^^^^^^^^^^^^^^^^^^^^^^^^^^^^^^^^^^^^^^^^^^^^^^^^^
  File "C:\Users\DELL\AppData\Local\Programs\Python\Python312\Lib\site-packages\aiohttp\connector.py", line 1056, in _create_connection
    _, proto = await self._create_direct_connection(req, traces, timeout)
               ^^^^^^^^^^^^^^^^^^^^^^^^^^^^^^^^^^^^^^^^^^^^^^^^^^^^^^^^^^
  File "C:\Users\DELL\AppData\Local\Programs\Python\Python312\Lib\site-packages\aiohttp\connector.py", line 1363, in _create_direct_connection
    raise ClientConnectorDNSError(req.connection_key, exc) from exc
aiohttp.client_exceptions.ClientConnectorDNSError: Cannot connect to host gateway-us-east1-b.discord.gg:443 ssl:default [getaddrinfo failed]
2025-05-14 18:31:52,547 - ERROR - Attempting a reconnect in 176.32s
Traceback (most recent call last):
  File "C:\Users\DELL\AppData\Local\Programs\Python\Python312\Lib\site-packages\aiohttp\connector.py", line 1357, in _create_direct_connection
    hosts = await self._resolve_host(host, port, traces=traces)
            ^^^^^^^^^^^^^^^^^^^^^^^^^^^^^^^^^^^^^^^^^^^^^^^^^^^
  File "C:\Users\DELL\AppData\Local\Programs\Python\Python312\Lib\site-packages\aiohttp\connector.py", line 995, in _resolve_host
    return await asyncio.shield(resolved_host_task)
           ^^^^^^^^^^^^^^^^^^^^^^^^^^^^^^^^^^^^^^^^
  File "C:\Users\DELL\AppData\Local\Programs\Python\Python312\Lib\site-packages\aiohttp\connector.py", line 1026, in _resolve_host_with_throttle
    addrs = await self._resolver.resolve(host, port, family=self._family)
            ^^^^^^^^^^^^^^^^^^^^^^^^^^^^^^^^^^^^^^^^^^^^^^^^^^^^^^^^^^^^^
  File "C:\Users\DELL\AppData\Local\Programs\Python\Python312\Lib\site-packages\aiohttp\resolver.py", line 39, in resolve
    infos = await self._loop.getaddrinfo(
            ^^^^^^^^^^^^^^^^^^^^^^^^^^^^^
  File "C:\Users\DELL\AppData\Local\Programs\Python\Python312\Lib\asyncio\base_events.py", line 901, in getaddrinfo
    return await self.run_in_executor(
           ^^^^^^^^^^^^^^^^^^^^^^^^^^^
  File "C:\Users\DELL\AppData\Local\Programs\Python\Python312\Lib\concurrent\futures\thread.py", line 58, in run
    result = self.fn(*self.args, **self.kwargs)
             ^^^^^^^^^^^^^^^^^^^^^^^^^^^^^^^^^^
  File "C:\Users\DELL\AppData\Local\Programs\Python\Python312\Lib\socket.py", line 963, in getaddrinfo
    for res in _socket.getaddrinfo(host, port, family, type, proto, flags):
               ^^^^^^^^^^^^^^^^^^^^^^^^^^^^^^^^^^^^^^^^^^^^^^^^^^^^^^^^^^^
socket.gaierror: [Errno 11001] getaddrinfo failed

The above exception was the direct cause of the following exception:

Traceback (most recent call last):
  File "C:\Users\DELL\AppData\Local\Programs\Python\Python312\Lib\site-packages\discord\client.py", line 701, in connect
    self.ws = await asyncio.wait_for(coro, timeout=60.0)
              ^^^^^^^^^^^^^^^^^^^^^^^^^^^^^^^^^^^^^^^^^^
  File "C:\Users\DELL\AppData\Local\Programs\Python\Python312\Lib\asyncio\tasks.py", line 520, in wait_for
    return await fut
           ^^^^^^^^^
  File "C:\Users\DELL\AppData\Local\Programs\Python\Python312\Lib\site-packages\discord\gateway.py", line 375, in from_client
    socket = await client.http.ws_connect(str(url))
             ^^^^^^^^^^^^^^^^^^^^^^^^^^^^^^^^^^^^^^
  File "C:\Users\DELL\AppData\Local\Programs\Python\Python312\Lib\site-packages\discord\http.py", line 554, in ws_connect
    return await self.__session.ws_connect(url, **kwargs)
           ^^^^^^^^^^^^^^^^^^^^^^^^^^^^^^^^^^^^^^^^^^^^^^
  File "C:\Users\DELL\AppData\Local\Programs\Python\Python312\Lib\site-packages\aiohttp\client.py", line 1004, in _ws_connect
    resp = await self.request(
           ^^^^^^^^^^^^^^^^^^^
  File "C:\Users\DELL\AppData\Local\Programs\Python\Python312\Lib\site-packages\aiohttp\client.py", line 703, in _request
    conn = await self._connector.connect(
           ^^^^^^^^^^^^^^^^^^^^^^^^^^^^^^
  File "C:\Users\DELL\AppData\Local\Programs\Python\Python312\Lib\site-packages\aiohttp\connector.py", line 548, in connect
    proto = await self._create_connection(req, traces, timeout)
            ^^^^^^^^^^^^^^^^^^^^^^^^^^^^^^^^^^^^^^^^^^^^^^^^^^^
  File "C:\Users\DELL\AppData\Local\Programs\Python\Python312\Lib\site-packages\aiohttp\connector.py", line 1056, in _create_connection
    _, proto = await self._create_direct_connection(req, traces, timeout)
               ^^^^^^^^^^^^^^^^^^^^^^^^^^^^^^^^^^^^^^^^^^^^^^^^^^^^^^^^^^
  File "C:\Users\DELL\AppData\Local\Programs\Python\Python312\Lib\site-packages\aiohttp\connector.py", line 1363, in _create_direct_connection
    raise ClientConnectorDNSError(req.connection_key, exc) from exc
aiohttp.client_exceptions.ClientConnectorDNSError: Cannot connect to host gateway-us-east1-b.discord.gg:443 ssl:default [getaddrinfo failed]
2025-05-14 18:34:50,224 - INFO - Shard ID None session has been invalidated.
2025-05-14 18:34:59,234 - INFO - Shard ID None has connected to Gateway (Session ID: b76d7cff2458bffc05d935c71aaf181b).
2025-05-14 18:35:01,799 - INFO - Initializing CoC client...
2025-05-14 18:35:03,658 - INFO - Successfully logged into the developer site.
2025-05-14 18:35:03,667 - INFO - Found IP address to be 103.247.51.91
2025-05-14 18:35:03,765 - ERROR - Unclosed connection
client_connection: Connection<ConnectionKey(host='gateway-us-east1-b.discord.gg', port=443, is_ssl=True, ssl=True, proxy=None, proxy_auth=None, proxy_headers_hash=None)>
2025-05-14 18:35:04,597 - INFO - Retrieved 1 valid keys from the developer site.
2025-05-14 18:35:04,598 - INFO - Successfully initialised keys for use.
2025-05-14 18:35:05,495 - INFO - CoC client initialized
2025-05-14 18:35:06,488 - INFO - Slash commands synced to server 1209053585418223646
2025-05-14 18:40:11,219 - ERROR - Attempting a reconnect in 207.68s
Traceback (most recent call last):
  File "C:\Users\DELL\AppData\Local\Programs\Python\Python312\Lib\site-packages\aiohttp\connector.py", line 1357, in _create_direct_connection
    hosts = await self._resolve_host(host, port, traces=traces)
            ^^^^^^^^^^^^^^^^^^^^^^^^^^^^^^^^^^^^^^^^^^^^^^^^^^^
  File "C:\Users\DELL\AppData\Local\Programs\Python\Python312\Lib\site-packages\aiohttp\connector.py", line 995, in _resolve_host
    return await asyncio.shield(resolved_host_task)
           ^^^^^^^^^^^^^^^^^^^^^^^^^^^^^^^^^^^^^^^^
  File "C:\Users\DELL\AppData\Local\Programs\Python\Python312\Lib\site-packages\aiohttp\connector.py", line 1026, in _resolve_host_with_throttle
    addrs = await self._resolver.resolve(host, port, family=self._family)
            ^^^^^^^^^^^^^^^^^^^^^^^^^^^^^^^^^^^^^^^^^^^^^^^^^^^^^^^^^^^^^
  File "C:\Users\DELL\AppData\Local\Programs\Python\Python312\Lib\site-packages\aiohttp\resolver.py", line 39, in resolve
    infos = await self._loop.getaddrinfo(
            ^^^^^^^^^^^^^^^^^^^^^^^^^^^^^
  File "C:\Users\DELL\AppData\Local\Programs\Python\Python312\Lib\asyncio\base_events.py", line 901, in getaddrinfo
    return await self.run_in_executor(
           ^^^^^^^^^^^^^^^^^^^^^^^^^^^
  File "C:\Users\DELL\AppData\Local\Programs\Python\Python312\Lib\concurrent\futures\thread.py", line 58, in run
    result = self.fn(*self.args, **self.kwargs)
             ^^^^^^^^^^^^^^^^^^^^^^^^^^^^^^^^^^
  File "C:\Users\DELL\AppData\Local\Programs\Python\Python312\Lib\socket.py", line 963, in getaddrinfo
    for res in _socket.getaddrinfo(host, port, family, type, proto, flags):
               ^^^^^^^^^^^^^^^^^^^^^^^^^^^^^^^^^^^^^^^^^^^^^^^^^^^^^^^^^^^
socket.gaierror: [Errno 11001] getaddrinfo failed

The above exception was the direct cause of the following exception:

Traceback (most recent call last):
  File "C:\Users\DELL\AppData\Local\Programs\Python\Python312\Lib\site-packages\discord\client.py", line 701, in connect
    self.ws = await asyncio.wait_for(coro, timeout=60.0)
              ^^^^^^^^^^^^^^^^^^^^^^^^^^^^^^^^^^^^^^^^^^
  File "C:\Users\DELL\AppData\Local\Programs\Python\Python312\Lib\asyncio\tasks.py", line 520, in wait_for
    return await fut
           ^^^^^^^^^
  File "C:\Users\DELL\AppData\Local\Programs\Python\Python312\Lib\site-packages\discord\gateway.py", line 375, in from_client
    socket = await client.http.ws_connect(str(url))
             ^^^^^^^^^^^^^^^^^^^^^^^^^^^^^^^^^^^^^^
  File "C:\Users\DELL\AppData\Local\Programs\Python\Python312\Lib\site-packages\discord\http.py", line 554, in ws_connect
    return await self.__session.ws_connect(url, **kwargs)
           ^^^^^^^^^^^^^^^^^^^^^^^^^^^^^^^^^^^^^^^^^^^^^^
  File "C:\Users\DELL\AppData\Local\Programs\Python\Python312\Lib\site-packages\aiohttp\client.py", line 1004, in _ws_connect
    resp = await self.request(
           ^^^^^^^^^^^^^^^^^^^
  File "C:\Users\DELL\AppData\Local\Programs\Python\Python312\Lib\site-packages\aiohttp\client.py", line 703, in _request
    conn = await self._connector.connect(
           ^^^^^^^^^^^^^^^^^^^^^^^^^^^^^^
  File "C:\Users\DELL\AppData\Local\Programs\Python\Python312\Lib\site-packages\aiohttp\connector.py", line 548, in connect
    proto = await self._create_connection(req, traces, timeout)
            ^^^^^^^^^^^^^^^^^^^^^^^^^^^^^^^^^^^^^^^^^^^^^^^^^^^
  File "C:\Users\DELL\AppData\Local\Programs\Python\Python312\Lib\site-packages\aiohttp\connector.py", line 1056, in _create_connection
    _, proto = await self._create_direct_connection(req, traces, timeout)
               ^^^^^^^^^^^^^^^^^^^^^^^^^^^^^^^^^^^^^^^^^^^^^^^^^^^^^^^^^^
  File "C:\Users\DELL\AppData\Local\Programs\Python\Python312\Lib\site-packages\aiohttp\connector.py", line 1363, in _create_direct_connection
    raise ClientConnectorDNSError(req.connection_key, exc) from exc
aiohttp.client_exceptions.ClientConnectorDNSError: Cannot connect to host gateway-us-east1-b.discord.gg:443 ssl:default [getaddrinfo failed]
2025-05-14 18:43:40,938 - INFO - Shard ID None session has been invalidated.
2025-05-14 18:43:47,738 - INFO - Shard ID None has connected to Gateway (Session ID: 7695c1115025e7faa0c18a79a5261998).
2025-05-14 18:43:50,229 - INFO - Initializing CoC client...
2025-05-14 18:43:52,093 - INFO - Successfully logged into the developer site.
2025-05-14 18:43:52,116 - INFO - Found IP address to be 103.247.51.91
2025-05-14 18:43:52,984 - INFO - Retrieved 1 valid keys from the developer site.
2025-05-14 18:43:53,012 - INFO - Successfully initialised keys for use.
2025-05-14 18:43:57,400 - INFO - CoC client initialized
2025-05-14 18:43:59,697 - INFO - Slash commands synced to server 1209053585418223646
2025-05-14 19:06:45,279 - ERROR - Attempting a reconnect in 175.62s
Traceback (most recent call last):
  File "C:\Users\DELL\AppData\Local\Programs\Python\Python312\Lib\site-packages\aiohttp\connector.py", line 1357, in _create_direct_connection
    hosts = await self._resolve_host(host, port, traces=traces)
            ^^^^^^^^^^^^^^^^^^^^^^^^^^^^^^^^^^^^^^^^^^^^^^^^^^^
  File "C:\Users\DELL\AppData\Local\Programs\Python\Python312\Lib\site-packages\aiohttp\connector.py", line 995, in _resolve_host
    return await asyncio.shield(resolved_host_task)
           ^^^^^^^^^^^^^^^^^^^^^^^^^^^^^^^^^^^^^^^^
  File "C:\Users\DELL\AppData\Local\Programs\Python\Python312\Lib\site-packages\aiohttp\connector.py", line 1026, in _resolve_host_with_throttle
    addrs = await self._resolver.resolve(host, port, family=self._family)
            ^^^^^^^^^^^^^^^^^^^^^^^^^^^^^^^^^^^^^^^^^^^^^^^^^^^^^^^^^^^^^
  File "C:\Users\DELL\AppData\Local\Programs\Python\Python312\Lib\site-packages\aiohttp\resolver.py", line 39, in resolve
    infos = await self._loop.getaddrinfo(
            ^^^^^^^^^^^^^^^^^^^^^^^^^^^^^
  File "C:\Users\DELL\AppData\Local\Programs\Python\Python312\Lib\asyncio\base_events.py", line 901, in getaddrinfo
    return await self.run_in_executor(
           ^^^^^^^^^^^^^^^^^^^^^^^^^^^
  File "C:\Users\DELL\AppData\Local\Programs\Python\Python312\Lib\concurrent\futures\thread.py", line 58, in run
    result = self.fn(*self.args, **self.kwargs)
             ^^^^^^^^^^^^^^^^^^^^^^^^^^^^^^^^^^
  File "C:\Users\DELL\AppData\Local\Programs\Python\Python312\Lib\socket.py", line 963, in getaddrinfo
    for res in _socket.getaddrinfo(host, port, family, type, proto, flags):
               ^^^^^^^^^^^^^^^^^^^^^^^^^^^^^^^^^^^^^^^^^^^^^^^^^^^^^^^^^^^
socket.gaierror: [Errno 11004] getaddrinfo failed

The above exception was the direct cause of the following exception:

Traceback (most recent call last):
  File "C:\Users\DELL\AppData\Local\Programs\Python\Python312\Lib\site-packages\discord\client.py", line 701, in connect
    self.ws = await asyncio.wait_for(coro, timeout=60.0)
              ^^^^^^^^^^^^^^^^^^^^^^^^^^^^^^^^^^^^^^^^^^
  File "C:\Users\DELL\AppData\Local\Programs\Python\Python312\Lib\asyncio\tasks.py", line 520, in wait_for
    return await fut
           ^^^^^^^^^
  File "C:\Users\DELL\AppData\Local\Programs\Python\Python312\Lib\site-packages\discord\gateway.py", line 375, in from_client
    socket = await client.http.ws_connect(str(url))
             ^^^^^^^^^^^^^^^^^^^^^^^^^^^^^^^^^^^^^^
  File "C:\Users\DELL\AppData\Local\Programs\Python\Python312\Lib\site-packages\discord\http.py", line 554, in ws_connect
    return await self.__session.ws_connect(url, **kwargs)
           ^^^^^^^^^^^^^^^^^^^^^^^^^^^^^^^^^^^^^^^^^^^^^^
  File "C:\Users\DELL\AppData\Local\Programs\Python\Python312\Lib\site-packages\aiohttp\client.py", line 1004, in _ws_connect
    resp = await self.request(
           ^^^^^^^^^^^^^^^^^^^
  File "C:\Users\DELL\AppData\Local\Programs\Python\Python312\Lib\site-packages\aiohttp\client.py", line 703, in _request
    conn = await self._connector.connect(
           ^^^^^^^^^^^^^^^^^^^^^^^^^^^^^^
  File "C:\Users\DELL\AppData\Local\Programs\Python\Python312\Lib\site-packages\aiohttp\connector.py", line 548, in connect
    proto = await self._create_connection(req, traces, timeout)
            ^^^^^^^^^^^^^^^^^^^^^^^^^^^^^^^^^^^^^^^^^^^^^^^^^^^
  File "C:\Users\DELL\AppData\Local\Programs\Python\Python312\Lib\site-packages\aiohttp\connector.py", line 1056, in _create_connection
    _, proto = await self._create_direct_connection(req, traces, timeout)
               ^^^^^^^^^^^^^^^^^^^^^^^^^^^^^^^^^^^^^^^^^^^^^^^^^^^^^^^^^^
  File "C:\Users\DELL\AppData\Local\Programs\Python\Python312\Lib\site-packages\aiohttp\connector.py", line 1363, in _create_direct_connection
    raise ClientConnectorDNSError(req.connection_key, exc) from exc
aiohttp.client_exceptions.ClientConnectorDNSError: Cannot connect to host gateway-us-east1-b.discord.gg:443 ssl:default [getaddrinfo failed]
2025-05-14 19:10:21,009 - ERROR - Attempting a reconnect in 957.33s
Traceback (most recent call last):
  File "C:\Users\DELL\AppData\Local\Programs\Python\Python312\Lib\site-packages\aiohttp\connector.py", line 1357, in _create_direct_connection
    hosts = await self._resolve_host(host, port, traces=traces)
            ^^^^^^^^^^^^^^^^^^^^^^^^^^^^^^^^^^^^^^^^^^^^^^^^^^^
  File "C:\Users\DELL\AppData\Local\Programs\Python\Python312\Lib\site-packages\aiohttp\connector.py", line 995, in _resolve_host
    return await asyncio.shield(resolved_host_task)
           ^^^^^^^^^^^^^^^^^^^^^^^^^^^^^^^^^^^^^^^^
  File "C:\Users\DELL\AppData\Local\Programs\Python\Python312\Lib\site-packages\aiohttp\connector.py", line 1026, in _resolve_host_with_throttle
    addrs = await self._resolver.resolve(host, port, family=self._family)
            ^^^^^^^^^^^^^^^^^^^^^^^^^^^^^^^^^^^^^^^^^^^^^^^^^^^^^^^^^^^^^
  File "C:\Users\DELL\AppData\Local\Programs\Python\Python312\Lib\site-packages\aiohttp\resolver.py", line 39, in resolve
    infos = await self._loop.getaddrinfo(
            ^^^^^^^^^^^^^^^^^^^^^^^^^^^^^
  File "C:\Users\DELL\AppData\Local\Programs\Python\Python312\Lib\asyncio\base_events.py", line 901, in getaddrinfo
    return await self.run_in_executor(
           ^^^^^^^^^^^^^^^^^^^^^^^^^^^
  File "C:\Users\DELL\AppData\Local\Programs\Python\Python312\Lib\concurrent\futures\thread.py", line 58, in run
    result = self.fn(*self.args, **self.kwargs)
             ^^^^^^^^^^^^^^^^^^^^^^^^^^^^^^^^^^
  File "C:\Users\DELL\AppData\Local\Programs\Python\Python312\Lib\socket.py", line 963, in getaddrinfo
    for res in _socket.getaddrinfo(host, port, family, type, proto, flags):
               ^^^^^^^^^^^^^^^^^^^^^^^^^^^^^^^^^^^^^^^^^^^^^^^^^^^^^^^^^^^
socket.gaierror: [Errno 11001] getaddrinfo failed

The above exception was the direct cause of the following exception:

Traceback (most recent call last):
  File "C:\Users\DELL\AppData\Local\Programs\Python\Python312\Lib\site-packages\discord\client.py", line 701, in connect
    self.ws = await asyncio.wait_for(coro, timeout=60.0)
              ^^^^^^^^^^^^^^^^^^^^^^^^^^^^^^^^^^^^^^^^^^
  File "C:\Users\DELL\AppData\Local\Programs\Python\Python312\Lib\asyncio\tasks.py", line 520, in wait_for
    return await fut
           ^^^^^^^^^
  File "C:\Users\DELL\AppData\Local\Programs\Python\Python312\Lib\site-packages\discord\gateway.py", line 375, in from_client
    socket = await client.http.ws_connect(str(url))
             ^^^^^^^^^^^^^^^^^^^^^^^^^^^^^^^^^^^^^^
  File "C:\Users\DELL\AppData\Local\Programs\Python\Python312\Lib\site-packages\discord\http.py", line 554, in ws_connect
    return await self.__session.ws_connect(url, **kwargs)
           ^^^^^^^^^^^^^^^^^^^^^^^^^^^^^^^^^^^^^^^^^^^^^^
  File "C:\Users\DELL\AppData\Local\Programs\Python\Python312\Lib\site-packages\aiohttp\client.py", line 1004, in _ws_connect
    resp = await self.request(
           ^^^^^^^^^^^^^^^^^^^
  File "C:\Users\DELL\AppData\Local\Programs\Python\Python312\Lib\site-packages\aiohttp\client.py", line 703, in _request
    conn = await self._connector.connect(
           ^^^^^^^^^^^^^^^^^^^^^^^^^^^^^^
  File "C:\Users\DELL\AppData\Local\Programs\Python\Python312\Lib\site-packages\aiohttp\connector.py", line 548, in connect
    proto = await self._create_connection(req, traces, timeout)
            ^^^^^^^^^^^^^^^^^^^^^^^^^^^^^^^^^^^^^^^^^^^^^^^^^^^
  File "C:\Users\DELL\AppData\Local\Programs\Python\Python312\Lib\site-packages\aiohttp\connector.py", line 1056, in _create_connection
    _, proto = await self._create_direct_connection(req, traces, timeout)
               ^^^^^^^^^^^^^^^^^^^^^^^^^^^^^^^^^^^^^^^^^^^^^^^^^^^^^^^^^^
  File "C:\Users\DELL\AppData\Local\Programs\Python\Python312\Lib\site-packages\aiohttp\connector.py", line 1363, in _create_direct_connection
    raise ClientConnectorDNSError(req.connection_key, exc) from exc
aiohttp.client_exceptions.ClientConnectorDNSError: Cannot connect to host gateway-us-east1-b.discord.gg:443 ssl:default [getaddrinfo failed]
